2017-07-19 17:00:03,008 - __main__ - ERROR - Exception on /nodes/myresult1 [PUT]
Traceback (most recent call last):
  File "/home/bouchair/PycharmProjects/VOSpace/env/lib/python3.5/site-packages/flask/app.py", line 1982, in wsgi_app
    response = self.full_dispatch_request()
  File "/home/bouchair/PycharmProjects/VOSpace/env/lib/python3.5/site-packages/flask/app.py", line 1614, in full_dispatch_request
    rv = self.handle_user_exception(e)
  File "/home/bouchair/PycharmProjects/VOSpace/env/lib/python3.5/site-packages/flask/app.py", line 1517, in handle_user_exception
    reraise(exc_type, exc_value, tb)
  File "/home/bouchair/PycharmProjects/VOSpace/env/lib/python3.5/site-packages/flask/_compat.py", line 33, in reraise
    raise value
  File "/home/bouchair/PycharmProjects/VOSpace/env/lib/python3.5/site-packages/flask/app.py", line 1612, in full_dispatch_request
    rv = self.dispatch_request()
  File "/home/bouchair/PycharmProjects/VOSpace/env/lib/python3.5/site-packages/flask/app.py", line 1598, in dispatch_request
    return self.view_functions[rule.endpoint](**req.view_args)
  File "app.py", line 68, in api_node
    xmltodict = Parser().xml_parser(request.data.decode("utf-8"))
  File "/home/bouchair/PycharmProjects/VOSpace/core/parser.py", line 43, in xml_parser
    xmltodict['properties'][ind].append(v)
KeyError: ''
